<?xml version='1.0' encoding='utf-8'?>
<robot name="a1">
  <link name="base">
    <visual>
      <origin rpy="0 0 0" xyz="0 0 0" />
      <geometry>
        <sphere radius="0.025" /></geometry>
    </visual>
  </link>
  <joint name="floating_base" type="fixed">
    <origin rpy="0 0 0" xyz="0.0 0.0 0.0" />
    <parent link="base" />
    <child link="trunk" />
  </joint>
  <link name="trunk">
    <visual>
      <origin xyz="0 0 0" />
      <geometry>
        <sphere radius="0.025" /></geometry>
      <material name="orange" />
    </visual>
    <collision>
      <origin rpy="0 0 0" xyz="0 0 0" />
      <geometry>
        <box size="0.267 0.194 0.114" />
      </geometry>
    </collision>
  </link>

  <link name="FR_pre_hip"><visual><geometry><cylinder length="1.0019502037066885" radius="0.01" /></geometry><origin xyz="-0.338593125 0.092315625 0.35750324999999994" rpy="2.8888896292894506 0.7421420083995249 2.5104703330084055" /></visual></link>
   <joint name="FR_pre_hip_joint" type="revolute">
    <origin rpy="0 0 0" xyz="0.67718625 -0.18463125 -0.7150064999999999" />
    <parent link="trunk" />
    <child link="FR_pre_hip" />
    <axis xyz="0 1 0" />
    <dynamics damping="0.01" friction="0.2" />
    <limit effort="33.5" velocity="21" />
  </joint>

  <joint name="FR_hip_joint" type="revolute">
    <origin rpy="0 0 0" xyz="0.0 0.0 0.0" />
    <parent link="FR_pre_hip" />
    <child link="FR_hip" />
    <axis xyz="1 0 0" />
    <dynamics damping="0.01" friction="0.2" />
    <limit effort="33.5" velocity="21" />
  </joint>
  <link name="FR_hip">
    <visual>
      <origin xyz="0 0 0" />
      <geometry>
        <sphere radius="0.025" /></geometry>
      <material name="orange" />
    </visual>
    <collision>
      <origin rpy="1.57079632679 0 0" xyz="0 0 0" />
      <geometry>
        <cylinder length="0.04" radius="0.046" />
      </geometry>
    </collision>
  </link>
  <joint name="FR_thigh_joint" type="revolute">
    <origin rpy="0 0 0" xyz="0.0 0.0 0.0" />
    <parent link="FR_hip" />
    <child link="FR_thigh" />
    <axis xyz="0 1 0" />
    <dynamics damping="0.01" friction="0.2" />
    <limit effort="33.5" velocity="21" />
  </joint>
  <link name="FR_thigh">
    <visual>
      <origin xyz="0 0 0" />
      <geometry>
        <sphere radius="0.025" /></geometry>
      <material name="orange" />
    </visual>
    <collision>
      <origin rpy="0 1.57079632679 0" xyz="0 0 -0.1" />
      <geometry>
        <box size="0.2 0.0245 0.034" />
      </geometry>
    </collision>
  </link>
  <joint name="FR_calf_joint" type="revolute">
    <origin rpy="0 0 0" xyz="-0.040931999999999996 0.0048765 -0.39978975" />
    <parent link="FR_thigh" />
    <child link="FR_calf" />
    <axis xyz="0 1 0" />
    <dynamics damping="0.01" friction="0.2" />
    <limit effort="33.5" velocity="21" />
  </joint>
  <link name="FR_calf">
    <visual>
      <origin xyz="0.020465999999999998 -0.00243825 0.199894875" rpy="-3.129395597074681 -0.10202076790541481 2.903814504463024" />
      <geometry>
        <cylinder length="0.4019092597605988" radius="0.01" /></geometry>
      <material name="orange" />
    </visual>
    <collision>
      <origin rpy="0 1.57079632679 0" xyz="0 0 -0.1" />
      <geometry>
        <box size="0.2 0.016 0.016" />
      </geometry>
    </collision>
  </link>
  <joint name="FR_foot_fixed" type="fixed">
    <origin rpy="0 0 0" xyz="-0.06624075000000001 -0.007538250000000001 -0.3411915" />
    <parent link="FR_calf" />
    <child link="FR_foot" />
  </joint>
  <link name="FR_foot">
    <visual>
      <origin xyz="0.03312037500000001 0.0037691250000000003 0.17059575" rpy="3.1195023500957944 -0.1917141746806199 -2.9128419192505857" />
      <geometry>
        <cylinder length="0.34764392968362756" radius="0.01" /></geometry>
      <material name="orange" />
    </visual>
    <collision>
      <origin rpy="0 0 0" xyz="0 0 0" />
      <geometry>
        <sphere radius="0.02" />
      </geometry>
    </collision>
  </link>
  <transmission name="FR_hip_tran">
    <type>transmission_interface/SimpleTransmission</type>
    <joint name="FR_hip_joint">
      <hardwareInterface>hardware_interface/EffortJointInterface</hardwareInterface>
    </joint>
    <actuator name="FR_hip_motor">
      <hardwareInterface>hardware_interface/EffortJointInterface</hardwareInterface>
      <mechanicalReduction>1</mechanicalReduction>
    </actuator>
  </transmission>
  <transmission name="FR_thigh_tran">
    <type>transmission_interface/SimpleTransmission</type>
    <joint name="FR_thigh_joint">
      <hardwareInterface>hardware_interface/EffortJointInterface</hardwareInterface>
    </joint>
    <actuator name="FR_thigh_motor">
      <hardwareInterface>hardware_interface/EffortJointInterface</hardwareInterface>
      <mechanicalReduction>1</mechanicalReduction>
    </actuator>
  </transmission>
  <transmission name="FR_calf_tran">
    <type>transmission_interface/SimpleTransmission</type>
    <joint name="FR_calf_joint">
      <hardwareInterface>hardware_interface/EffortJointInterface</hardwareInterface>
    </joint>
    <actuator name="FR_calf_motor">
      <hardwareInterface>hardware_interface/EffortJointInterface</hardwareInterface>
      <mechanicalReduction>1</mechanicalReduction>
    </actuator>
  </transmission>
  <link name="FL_pre_hip"><visual><geometry><cylinder length="0.9194863621860782" radius="0.01" /></geometry><origin xyz="-0.273208875 -0.071692125 0.362740875" rpy="-2.9464673019675973 0.6363503674152082 -2.5638986988138943" /></visual></link>
   <joint name="FL_pre_hip_joint" type="revolute">
    <origin rpy="0 0 0" xyz="0.54641775 0.14338425 -0.72548175" />
    <parent link="trunk" />
    <child link="FL_pre_hip" />
    <axis xyz="0 1 0" />
    <dynamics damping="0.01" friction="0.2" />
    <limit effort="33.5" velocity="21" />
  </joint>
  <joint name="FL_hip_joint" type="revolute">
    <origin rpy="0 0 0" xyz="0.0 0.0 0.0" />
    <parent link="FL_pre_hip" />
    <child link="FL_hip" />
    <axis xyz="1 0 0" />
    <dynamics damping="0.01" friction="0.2" />
    <limit effort="33.5" velocity="21" />
  </joint>
  <link name="FL_hip">
    <visual>
      <origin xyz="0 0 0" />
      <geometry>
        <sphere radius="0.025" /></geometry>
      <material name="orange" />
    </visual>
    <collision>
      <origin rpy="1.57079632679 0 0" xyz="0 0 0" />
      <geometry>
        <cylinder length="0.04" radius="0.046" />
      </geometry>
    </collision>
  </link>
  <joint name="FL_thigh_joint" type="revolute">
    <origin rpy="0 0 0" xyz="0.0 0.0 0.0" />
    <parent link="FL_hip" />
    <child link="FL_thigh" />
    <axis xyz="0 1 0" />
    <dynamics damping="0.01" friction="0.2" />
    <limit effort="33.5" velocity="21" />
  </joint>
  <link name="FL_thigh">
    <visual>
      <origin xyz="0 0 0" />
      <geometry>
        <sphere radius="0.025" /></geometry>
      <material name="orange" />
    </visual>
    <collision>
      <origin rpy="0 1.57079632679 0" xyz="0 0 -0.1" />
      <geometry>
        <box size="0.2 0.0245 0.034" />
      </geometry>
    </collision>
  </link>
  <joint name="FL_calf_joint" type="revolute">
    <origin rpy="0 0 0" xyz="-0.04093125 0.0048765 -0.39978975" />
    <parent link="FL_thigh" />
    <child link="FL_calf" />
    <axis xyz="0 1 0" />
    <dynamics damping="0.01" friction="0.2" />
    <limit effort="33.5" velocity="21" />
  </joint>
  <link name="FL_calf">
    <visual>
      <origin xyz="0.020465625 -0.00243825 0.199894875" rpy="-3.129395597074681 -0.10201891151515086 2.903810210938718" />
      <geometry>
        <cylinder length="0.4019091833783784" radius="0.01" /></geometry>
      <material name="orange" />
    </visual>
    <collision>
      <origin rpy="0 1.57079632679 0" xyz="0 0 -0.1" />
      <geometry>
        <box size="0.2 0.016 0.016" />
      </geometry>
    </collision>
  </link>
  <joint name="FL_foot_fixed" type="fixed">
    <origin rpy="0 0 0" xyz="-0.06624075000000001 -0.007538250000000001 -0.3411915" />
    <parent link="FL_calf" />
    <child link="FL_foot" />
  </joint>
  <link name="FL_foot">
    <visual>
      <origin xyz="0.03312037500000001 0.0037691250000000003 0.17059575" rpy="3.1195023500957944 -0.1917141746806199 -2.9128419192505857" />
      <geometry>
        <cylinder length="0.34764392968362756" radius="0.01" /></geometry>
      <material name="orange" />
    </visual>
    <collision>
      <origin rpy="0 0 0" xyz="0 0 0" />
      <geometry>
        <sphere radius="0.02" />
      </geometry>
    </collision>
  </link>
  <transmission name="FL_hip_tran">
    <type>transmission_interface/SimpleTransmission</type>
    <joint name="FL_hip_joint">
      <hardwareInterface>hardware_interface/EffortJointInterface</hardwareInterface>
    </joint>
    <actuator name="FL_hip_motor">
      <hardwareInterface>hardware_interface/EffortJointInterface</hardwareInterface>
      <mechanicalReduction>1</mechanicalReduction>
    </actuator>
  </transmission>
  <transmission name="FL_thigh_tran">
    <type>transmission_interface/SimpleTransmission</type>
    <joint name="FL_thigh_joint">
      <hardwareInterface>hardware_interface/EffortJointInterface</hardwareInterface>
    </joint>
    <actuator name="FL_thigh_motor">
      <hardwareInterface>hardware_interface/EffortJointInterface</hardwareInterface>
      <mechanicalReduction>1</mechanicalReduction>
    </actuator>
  </transmission>
  <transmission name="FL_calf_tran">
    <type>transmission_interface/SimpleTransmission</type>
    <joint name="FL_calf_joint">
      <hardwareInterface>hardware_interface/EffortJointInterface</hardwareInterface>
    </joint>
    <actuator name="FL_calf_motor">
      <hardwareInterface>hardware_interface/EffortJointInterface</hardwareInterface>
      <mechanicalReduction>1</mechanicalReduction>
    </actuator>
  </transmission>
  <link name="RR_pre_hip"><visual><geometry><cylinder length="0.8827539329724409" radius="0.01" /></geometry><origin xyz="0.309879 0.06767625000000001 0.30693412500000006" rpy="2.924573946616905 -0.7783048968371671 -2.622270256176068" /></visual></link>
   <joint name="RR_pre_hip_joint" type="revolute">
    <origin rpy="0 0 0" xyz="-0.619758 -0.13535250000000001 -0.6138682500000001" />
    <parent link="trunk" />
    <child link="RR_pre_hip" />
    <axis xyz="0 1 0" />
    <dynamics damping="0.01" friction="0.2" />
    <limit effort="33.5" velocity="21" />
  </joint>
  <joint name="RR_hip_joint" type="revolute">
    <origin rpy="0 0 0" xyz="0.0 0.0 0.0" />
    <parent link="RR_pre_hip" />
    <child link="RR_hip" />
    <axis xyz="1 0 0" />
    <dynamics damping="0.01" friction="0.2" />
    <limit effort="33.5" velocity="21" />
  </joint>
  <link name="RR_hip">
    <visual>
      <origin xyz="0 0 0" />
      <geometry>
        <sphere radius="0.025" /></geometry>
      <material name="orange" />
    </visual>
    <collision>
      <origin rpy="1.57079632679 0 0" xyz="0 0 0" />
      <geometry>
        <cylinder length="0.04" radius="0.046" />
      </geometry>
    </collision>
  </link>
  <joint name="RR_thigh_joint" type="revolute">
    <origin rpy="0 0 0" xyz="0.0 0.0 0.0" />
    <parent link="RR_hip" />
    <child link="RR_thigh" />
    <axis xyz="0 1 0" />
    <dynamics damping="0.01" friction="0.2" />
    <limit effort="33.5" velocity="21" />
  </joint>
  <link name="RR_thigh">
    <visual>
      <origin xyz="0 0 0" />
      <geometry>
        <sphere radius="0.025" /></geometry>
      <material name="orange" />
    </visual>
    <collision>
      <origin rpy="0 1.57079632679 0" xyz="0 0 -0.1" />
      <geometry>
        <box size="0.2 0.0245 0.034" />
      </geometry>
    </collision>
  </link>
  <joint name="RR_calf_joint" type="revolute">
    <origin rpy="0 0 0" xyz="-0.33638925 0.00455925 -0.5450107499999999" />
    <parent link="RR_thigh" />
    <child link="RR_calf" />
    <axis xyz="0 1 0" />
    <dynamics damping="0.01" friction="0.2" />
    <limit effort="33.5" velocity="21" />
  </joint>
  <link name="RR_calf">
    <visual>
      <origin xyz="0.168194625 -0.002279625 0.27250537499999994" rpy="-3.1332274173963977 -0.552966462380716 3.1121136698649328" />
      <geometry>
        <cylinder length="0.6404804695630362" radius="0.01" /></geometry>
      <material name="orange" />
    </visual>
    <collision>
      <origin rpy="0 1.57079632679 0" xyz="0 0 -0.1" />
      <geometry>
        <box size="0.2 0.016 0.016" />
      </geometry>
    </collision>
  </link>
  <joint name="RR_foot_fixed" type="fixed">
    <origin rpy="0 0 0" xyz="-0.056673749999999995 0.02511825 -0.3349125" />
    <parent link="RR_calf" />
    <child link="RR_foot" />
  </joint>
  <link name="RR_foot">
    <visual>
      <origin xyz="0.028336874999999997 -0.012559125 0.16745625" rpy="-3.0667333625952424 -0.1671707853352058 2.300935542511723" />
      <geometry>
        <cylinder length="0.3406012669946708" radius="0.01" /></geometry>
      <material name="orange" />
    </visual>
    <collision>
      <origin rpy="0 0 0" xyz="0 0 0" />
      <geometry>
        <sphere radius="0.02" />
      </geometry>
    </collision>
  </link>


  
  <link name="Lower Spine"><visual><geometry><cylinder length="0.42227883298605257" radius="0.01" /></geometry><origin xyz="0.21108787499999998 -0.004665 -0.0" rpy="-1.5707963267948868 -1.5487001227442672 1.5487001227442576" /></visual></link>

  <joint name="Spinal Midpoint Lower" type="revolute">
    <origin rpy="0 0 0" xyz="-0.42217574999999996 0.00933 0.0" />
    <parent link="trunk" />
    <child link="Lower Spine" />
    <axis xyz="0 1 0" />
    <dynamics damping="0.01" friction="0.2" />
    <limit effort="33.5" velocity="21" />
  </joint>

  <link name="Tail"><visual><geometry><cylinder length="0.8740386629466829" radius="0.01" /></geometry><origin xyz="0.339931875 -0.007512375 0.2745465" rpy="-3.1142366285110614 -0.8912242695321554 3.0843331857774268" /></visual></link>

  <joint name="Start of Tail" type="revolute">
    <origin rpy="0 0 0" xyz="-0.67986375 0.01502475 -0.549093" />
    <parent link="Lower Spine" />
    <child link="Tail" />
    <axis xyz="0 1 0" />
    <dynamics damping="0.01" friction="0.2" />
    <limit effort="33.5" velocity="21" />
  </joint>


  <link name="Upper Spine"><visual><geometry><cylinder length="0.3707540032211385" radius="0.01" /></geometry><origin xyz="-0.18533175 0.00409575 -0.0" rpy="1.5707963267948883 1.548700364175645 1.5487003641756367" /></visual></link>
  <link name="Ears"><visual><geometry><cylinder length="1.0238648565322843" radius="0.01" /></geometry><origin xyz="-0.4260637500000001 0.009415875 -0.28364737500000003" rpy="0.03318352112958867 0.9831819856331632 0.017768732540170137" /></visual></link>
  <link name="Nose"><visual><geometry><cylinder length="0.5798669370175583" radius="0.01" /></geometry><origin xyz="-0.21394237499999996 0.0047279999999999996 0.19562137500000001" rpy="3.1174282200942374 0.8299559115836823 3.086754670960559" /></visual></link>
  <link name="Jawline"><visual><geometry><cylinder length="0.43479036828280826" radius="0.01" /></geometry><origin xyz="0.21729675 -0.00480225 -0.004441499999999999" rpy="-0.8244047375174203 -1.540702369152888 0.802534125052207" /></visual></link>

  <joint name="Spinal Midpoint Upper" type="revolute">
    <origin rpy="0 0 0" xyz="0.3706635 -0.0081915 0.0" />
    <parent link="trunk" />
    <child link="Upper Spine" />
    <axis xyz="0 1 0" />
    <dynamics damping="0.01" friction="0.2" />
    <limit effort="33.5" velocity="21" />
  </joint>

  <joint name="Craniovertebral Junction" type="revolute">
    <origin rpy="0 0 0" xyz="0.8521275000000001 -0.01883175 0.5672947500000001" />
    <parent link="Upper Spine" />
    <child link="Ears" />
    <axis xyz="0 1 0" />
    <dynamics damping="0.01" friction="0.2" />
    <limit effort="33.5" velocity="21" />
  </joint>

  <joint name="Top of Nose" type="revolute">
    <origin rpy="0 0 0" xyz="0.4278847499999999 -0.009455999999999999 -0.39124275000000003" />
    <parent link="Ears" />
    <child link="Nose" />
    <axis xyz="0 1 0" />
    <dynamics damping="0.01" friction="0.2" />
    <limit effort="33.5" velocity="21" />
  </joint>

  <joint name="Jaw" type="revolute">
    <origin rpy="0 0 0" xyz="-0.4345935 0.0096045 0.008882999999999999" />
    <parent link="Nose" />
    <child link="Jawline" />
    <axis xyz="0 1 0" />
    <dynamics damping="0.01" friction="0.2" />
    <limit effort="33.5" velocity="21" />
  </joint>

  <transmission name="RR_hip_tran">
    <type>transmission_interface/SimpleTransmission</type>
    <joint name="RR_hip_joint">
      <hardwareInterface>hardware_interface/EffortJointInterface</hardwareInterface>
    </joint>
    <actuator name="RR_hip_motor">
      <hardwareInterface>hardware_interface/EffortJointInterface</hardwareInterface>
      <mechanicalReduction>1</mechanicalReduction>
    </actuator>
  </transmission>
  <transmission name="RR_thigh_tran">
    <type>transmission_interface/SimpleTransmission</type>
    <joint name="RR_thigh_joint">
      <hardwareInterface>hardware_interface/EffortJointInterface</hardwareInterface>
    </joint>
    <actuator name="RR_thigh_motor">
      <hardwareInterface>hardware_interface/EffortJointInterface</hardwareInterface>
      <mechanicalReduction>1</mechanicalReduction>
    </actuator>
  </transmission>
  <transmission name="RR_calf_tran">
    <type>transmission_interface/SimpleTransmission</type>
    <joint name="RR_calf_joint">
      <hardwareInterface>hardware_interface/EffortJointInterface</hardwareInterface>
    </joint>
    <actuator name="RR_calf_motor">
      <hardwareInterface>hardware_interface/EffortJointInterface</hardwareInterface>
      <mechanicalReduction>1</mechanicalReduction>
    </actuator>
  </transmission>
    <link name="RL_pre_hip"><visual><geometry><cylinder length="0.7475148583107312" radius="0.01" /></geometry><origin xyz="0.21185325 -0.08241187500000001 0.2966835" rpy="-2.8706464551574515 -0.6026409492454187 2.3149351973389396" /></visual></link>
    <joint name="RL_pre_hip_joint" type="revolute">
    <origin rpy="0 0 0" xyz="-0.4237065 0.16482375000000002 -0.593367" />
    <parent link="trunk" />
    <child link="RL_pre_hip" />
    <axis xyz="0 1 0" />
    <dynamics damping="0.01" friction="0.2" />
    <limit effort="33.5" velocity="21" />
  </joint>
  <joint name="RL_hip_joint" type="revolute">
    <origin rpy="0 0 0" xyz="0.0 0.0 0.0" />
    <parent link="RL_pre_hip" />
    <child link="RL_hip" />
    <axis xyz="1 0 0" />
    <dynamics damping="0.01" friction="0.2" />
    <limit effort="33.5" velocity="21" />
  </joint>
  <link name="RL_hip">
    <visual>
      <origin xyz="0 0 0" />
      <geometry>
        <sphere radius="0.025" /></geometry>
      <material name="orange" />
    </visual>
    <collision>
      <origin rpy="1.57079632679 0 0" xyz="0 0 0" />
      <geometry>
        <cylinder length="0.04" radius="0.046" />
      </geometry>
    </collision>
  </link>
  <joint name="RL_thigh_joint" type="revolute">
    <origin rpy="0 0 0" xyz="0.0 0.0 0.0" />
    <parent link="RL_hip" />
    <child link="RL_thigh" />
    <axis xyz="0 1 0" />
    <dynamics damping="0.01" friction="0.2" />
    <limit effort="33.5" velocity="21" />
  </joint>
  <link name="RL_thigh">
    <visual>
      <origin xyz="0 0 0" />
      <geometry>
        <sphere radius="0.025" /></geometry>
      <material name="orange" />
    </visual>
    <collision>
      <origin rpy="0 1.57079632679 0" xyz="0 0 -0.1" />
      <geometry>
        <box size="0.2 0.0245 0.034" />
      </geometry>
    </collision>
  </link>
  <joint name="RL_calf_joint" type="revolute">
    <origin rpy="0 0 0" xyz="-0.260238 0.009722999999999999 -0.5319044999999999" />
    <parent link="RL_thigh" />
    <child link="RL_calf" />
    <axis xyz="0 1 0" />
    <dynamics damping="0.01" friction="0.2" />
    <limit effort="33.5" velocity="21" />
  </joint>
  <link name="RL_calf">
    <visual>
      <origin xyz="0.130119 -0.0048614999999999995 0.26595224999999995" rpy="-3.1233150920022865 -0.4549503929715488 3.0626724546699977" />
      <geometry>
        <cylinder length="0.5922336958441742" radius="0.01" /></geometry>
      <material name="orange" />
    </visual>
    <collision>
      <origin rpy="0 1.57079632679 0" xyz="0 0 -0.1" />
      <geometry>
        <box size="0.2 0.016 0.016" />
      </geometry>
    </collision>
  </link>
  <joint name="RL_foot_fixed" type="fixed">
    <origin rpy="0 0 0" xyz="0.023230499999999998 -0.00951525 -0.3411915" />
    <parent link="RL_calf" />
    <child link="RL_foot" />
  </joint>
  <link name="RL_foot">
    <visual>
      <origin xyz="-0.011615249999999999 0.004757625 0.17059575" rpy="3.1137115829905664 0.06795513837847911 2.363132660877021" />
      <geometry>
        <cylinder length="0.34211377608196736" radius="0.01" /></geometry>
      <material name="orange" />
    </visual>
    <collision>
      <origin rpy="0 0 0" xyz="0 0 0" />
      <geometry>
        <sphere radius="0.02" />
      </geometry>
    </collision>
  </link>
  <transmission name="RL_hip_tran">
    <type>transmission_interface/SimpleTransmission</type>
    <joint name="RL_hip_joint">
      <hardwareInterface>hardware_interface/EffortJointInterface</hardwareInterface>
    </joint>
    <actuator name="RL_hip_motor">
      <hardwareInterface>hardware_interface/EffortJointInterface</hardwareInterface>
      <mechanicalReduction>1</mechanicalReduction>
    </actuator>
  </transmission>
  <transmission name="RL_thigh_tran">
    <type>transmission_interface/SimpleTransmission</type>
    <joint name="RL_thigh_joint">
      <hardwareInterface>hardware_interface/EffortJointInterface</hardwareInterface>
    </joint>
    <actuator name="RL_thigh_motor">
      <hardwareInterface>hardware_interface/EffortJointInterface</hardwareInterface>
      <mechanicalReduction>1</mechanicalReduction>
    </actuator>
  </transmission>
  <transmission name="RL_calf_tran">
    <type>transmission_interface/SimpleTransmission</type>
    <joint name="RL_calf_joint">
      <hardwareInterface>hardware_interface/EffortJointInterface</hardwareInterface>
    </joint>
    <actuator name="RL_calf_motor">
      <hardwareInterface>hardware_interface/EffortJointInterface</hardwareInterface>
      <mechanicalReduction>1</mechanicalReduction>
    </actuator>
  </transmission>
  
</robot>