<robot name="a1">
  <link name="base">
    <visual>
      <origin rpy="0 0 0" xyz="0 0 0" />
      <geometry>
        <sphere radius="0.1" /></geometry>
    </visual>
  </link>
  <joint name="floating_base" type="fixed">
    <origin rpy="0 0 0" xyz="0.0 0.0 0.0" />
    <parent link="base" />
    <child link="trunk" />
  </joint>
  <link name="trunk">
    <visual>
      <origin rpy="0 0 0" xyz="0 0 0" />
      <geometry>
        <sphere radius="0.1" /></geometry>
      <material name="orange" />
    </visual>
    <collision>
      <origin rpy="0 0 0" xyz="0 0 0" />
      <geometry>
        <box size="0.267 0.194 0.114" />
      </geometry>
    </collision>
  </link>

  <link name="FR_pre_hip"><visual><geometry><sphere radius="0.1" /></geometry></visual></link>
   <joint name="FR_pre_hip_joint" type="revolute">
    <origin rpy="0 0 0" xyz="0.902915 -0.246175 -0.9533419999999999" />
    <parent link="trunk" />
    <child link="FR_pre_hip" />
    <axis xyz="0 1 0" />
    <dynamics damping="0.01" friction="0.2" />
    <limit effort="33.5" velocity="21" />
  </joint>

  <joint name="FR_hip_joint" type="revolute">
    <origin rpy="0 0 0" xyz="0.0 0.0 0.0" />
    <parent link="FR_pre_hip" />
    <child link="FR_hip" />
    <axis xyz="1 0 0" />
    <dynamics damping="0.01" friction="0.2" />
    <limit effort="33.5" velocity="21" />
  </joint>
  <link name="FR_hip">
    <visual>
      <origin rpy="3.14159265359 0 0" xyz="0 0 0" />
      <geometry>
        <sphere radius="0.1" /></geometry>
      <material name="orange" />
    </visual>
    <collision>
      <origin rpy="1.57079632679 0 0" xyz="0 0 0" />
      <geometry>
        <cylinder length="0.04" radius="0.046" />
      </geometry>
    </collision>
  </link>
  <joint name="FR_thigh_joint" type="revolute">
    <origin rpy="0 0 0" xyz="0.0 0.0 0.0" />
    <parent link="FR_hip" />
    <child link="FR_thigh" />
    <axis xyz="0 1 0" />
    <dynamics damping="0.01" friction="0.2" />
    <limit effort="33.5" velocity="21" />
  </joint>
  <link name="FR_thigh">
    <visual>
      <origin rpy="0 0 0" xyz="0 0 0" />
      <geometry>
        <sphere radius="0.1" /></geometry>
      <material name="orange" />
    </visual>
    <collision>
      <origin rpy="0 1.57079632679 0" xyz="0 0 -0.1" />
      <geometry>
        <box size="0.2 0.0245 0.034" />
      </geometry>
    </collision>
  </link>
  <joint name="FR_calf_joint" type="revolute">
    <origin rpy="0 0 0" xyz="-0.054576 0.006502 -0.533053" />
    <parent link="FR_thigh" />
    <child link="FR_calf" />
    <axis xyz="0 1 0" />
    <dynamics damping="0.01" friction="0.2" />
    <limit effort="33.5" velocity="21" />
  </joint>
  <link name="FR_calf">
    <visual>
      <origin rpy="0 0 0" xyz="0 0 0" />
      <geometry>
        <sphere radius="0.1" /></geometry>
      <material name="orange" />
    </visual>
    <collision>
      <origin rpy="0 1.57079632679 0" xyz="0 0 -0.1" />
      <geometry>
        <box size="0.2 0.016 0.016" />
      </geometry>
    </collision>
  </link>
  <joint name="FR_foot_fixed" type="fixed">
    <origin rpy="0 0 0" xyz="-0.08832100000000001 -0.010051000000000001 -0.454922" />
    <parent link="FR_calf" />
    <child link="FR_foot" />
  </joint>
  <link name="FR_foot">
    <visual>
      <origin rpy="0 0 0" xyz="0 0 0" />
      <geometry>
        <sphere radius="0.1" /></geometry>
      <material name="orange" />
    </visual>
    <collision>
      <origin rpy="0 0 0" xyz="0 0 0" />
      <geometry>
        <sphere radius="0.02" />
      </geometry>
    </collision>
  </link>
  <transmission name="FR_hip_tran">
    <type>transmission_interface/SimpleTransmission</type>
    <joint name="FR_hip_joint">
      <hardwareInterface>hardware_interface/EffortJointInterface</hardwareInterface>
    </joint>
    <actuator name="FR_hip_motor">
      <hardwareInterface>hardware_interface/EffortJointInterface</hardwareInterface>
      <mechanicalReduction>1</mechanicalReduction>
    </actuator>
  </transmission>
  <transmission name="FR_thigh_tran">
    <type>transmission_interface/SimpleTransmission</type>
    <joint name="FR_thigh_joint">
      <hardwareInterface>hardware_interface/EffortJointInterface</hardwareInterface>
    </joint>
    <actuator name="FR_thigh_motor">
      <hardwareInterface>hardware_interface/EffortJointInterface</hardwareInterface>
      <mechanicalReduction>1</mechanicalReduction>
    </actuator>
  </transmission>
  <transmission name="FR_calf_tran">
    <type>transmission_interface/SimpleTransmission</type>
    <joint name="FR_calf_joint">
      <hardwareInterface>hardware_interface/EffortJointInterface</hardwareInterface>
    </joint>
    <actuator name="FR_calf_motor">
      <hardwareInterface>hardware_interface/EffortJointInterface</hardwareInterface>
      <mechanicalReduction>1</mechanicalReduction>
    </actuator>
  </transmission>
  <link name="FL_pre_hip"><visual><geometry><sphere radius="0.1" /></geometry></visual></link>
   <joint name="FL_pre_hip_joint" type="revolute">
    <origin rpy="0 0 0" xyz="0.728557 0.191179 -0.9673090000000001" />
    <parent link="trunk" />
    <child link="FL_pre_hip" />
    <axis xyz="0 1 0" />
    <dynamics damping="0.01" friction="0.2" />
    <limit effort="33.5" velocity="21" />
  </joint>
  <joint name="FL_hip_joint" type="revolute">
    <origin rpy="0 0 0" xyz="0.0 0.0 0.0" />
    <parent link="FL_pre_hip" />
    <child link="FL_hip" />
    <axis xyz="1 0 0" />
    <dynamics damping="0.01" friction="0.2" />
    <limit effort="33.5" velocity="21" />
  </joint>
  <link name="FL_hip">
    <visual>
      <origin rpy="0 0 0" xyz="0 0 0" />
      <geometry>
        <sphere radius="0.1" /></geometry>
      <material name="orange" />
    </visual>
    <collision>
      <origin rpy="1.57079632679 0 0" xyz="0 0 0" />
      <geometry>
        <cylinder length="0.04" radius="0.046" />
      </geometry>
    </collision>
  </link>
  <joint name="FL_thigh_joint" type="revolute">
    <origin rpy="0 0 0" xyz="0.0 0.0 0.0" />
    <parent link="FL_hip" />
    <child link="FL_thigh" />
    <axis xyz="0 1 0" />
    <dynamics damping="0.01" friction="0.2" />
    <limit effort="33.5" velocity="21" />
  </joint>
  <link name="FL_thigh">
    <visual>
      <origin rpy="0 0 0" xyz="0 0 0" />
      <geometry>
        <sphere radius="0.1" /></geometry>
      <material name="orange" />
    </visual>
    <collision>
      <origin rpy="0 1.57079632679 0" xyz="0 0 -0.1" />
      <geometry>
        <box size="0.2 0.0245 0.034" />
      </geometry>
    </collision>
  </link>
  <joint name="FL_calf_joint" type="revolute">
    <origin rpy="0 0 0" xyz="-0.054575 0.006502 -0.533053" />
    <parent link="FL_thigh" />
    <child link="FL_calf" />
    <axis xyz="0 1 0" />
    <dynamics damping="0.01" friction="0.2" />
    <limit effort="33.5" velocity="21" />
  </joint>
  <link name="FL_calf">
    <visual>
      <origin rpy="0 0 0" xyz="0 0 0" />
      <geometry>
        <sphere radius="0.1" /></geometry>
      <material name="orange" />
    </visual>
    <collision>
      <origin rpy="0 1.57079632679 0" xyz="0 0 -0.1" />
      <geometry>
        <box size="0.2 0.016 0.016" />
      </geometry>
    </collision>
  </link>
  <joint name="FL_foot_fixed" type="fixed">
    <origin rpy="0 0 0" xyz="-0.08832100000000001 -0.010051000000000001 -0.454922" />
    <parent link="FL_calf" />
    <child link="FL_foot" />
  </joint>
  <link name="FL_foot">
    <visual>
      <origin rpy="0 0 0" xyz="0 0 0" />
      <geometry>
        <sphere radius="0.1" /></geometry>
      <material name="orange" />
    </visual>
    <collision>
      <origin rpy="0 0 0" xyz="0 0 0" />
      <geometry>
        <sphere radius="0.02" />
      </geometry>
    </collision>
  </link>
  <transmission name="FL_hip_tran">
    <type>transmission_interface/SimpleTransmission</type>
    <joint name="FL_hip_joint">
      <hardwareInterface>hardware_interface/EffortJointInterface</hardwareInterface>
    </joint>
    <actuator name="FL_hip_motor">
      <hardwareInterface>hardware_interface/EffortJointInterface</hardwareInterface>
      <mechanicalReduction>1</mechanicalReduction>
    </actuator>
  </transmission>
  <transmission name="FL_thigh_tran">
    <type>transmission_interface/SimpleTransmission</type>
    <joint name="FL_thigh_joint">
      <hardwareInterface>hardware_interface/EffortJointInterface</hardwareInterface>
    </joint>
    <actuator name="FL_thigh_motor">
      <hardwareInterface>hardware_interface/EffortJointInterface</hardwareInterface>
      <mechanicalReduction>1</mechanicalReduction>
    </actuator>
  </transmission>
  <transmission name="FL_calf_tran">
    <type>transmission_interface/SimpleTransmission</type>
    <joint name="FL_calf_joint">
      <hardwareInterface>hardware_interface/EffortJointInterface</hardwareInterface>
    </joint>
    <actuator name="FL_calf_motor">
      <hardwareInterface>hardware_interface/EffortJointInterface</hardwareInterface>
      <mechanicalReduction>1</mechanicalReduction>
    </actuator>
  </transmission>
  <link name="RR_pre_hip"><visual><geometry><sphere radius="0.1" /></geometry></visual></link>
   <joint name="RR_pre_hip_joint" type="revolute">
    <origin rpy="0 0 0" xyz="-0.826344 -0.18047000000000002 -0.8184910000000001" />
    <parent link="trunk" />
    <child link="RR_pre_hip" />
    <axis xyz="0 1 0" />
    <dynamics damping="0.01" friction="0.2" />
    <limit effort="33.5" velocity="21" />
  </joint>
  <joint name="RR_hip_joint" type="revolute">
    <origin rpy="0 0 0" xyz="0.0 0.0 0.0" />
    <parent link="RR_pre_hip" />
    <child link="RR_hip" />
    <axis xyz="1 0 0" />
    <dynamics damping="0.01" friction="0.2" />
    <limit effort="33.5" velocity="21" />
  </joint>
  <link name="RR_hip">
    <visual>
      <origin rpy="3.14159265359 3.14159265359 0" xyz="0 0 0" />
      <geometry>
        <sphere radius="0.1" /></geometry>
      <material name="orange" />
    </visual>
    <collision>
      <origin rpy="1.57079632679 0 0" xyz="0 0 0" />
      <geometry>
        <cylinder length="0.04" radius="0.046" />
      </geometry>
    </collision>
  </link>
  <joint name="RR_thigh_joint" type="revolute">
    <origin rpy="0 0 0" xyz="0.0 0.0 0.0" />
    <parent link="RR_hip" />
    <child link="RR_thigh" />
    <axis xyz="0 1 0" />
    <dynamics damping="0.01" friction="0.2" />
    <limit effort="33.5" velocity="21" />
  </joint>
  <link name="RR_thigh">
    <visual>
      <origin rpy="0 0 0" xyz="0 0 0" />
      <geometry>
        <sphere radius="0.1" /></geometry>
      <material name="orange" />
    </visual>
    <collision>
      <origin rpy="0 1.57079632679 0" xyz="0 0 -0.1" />
      <geometry>
        <box size="0.2 0.0245 0.034" />
      </geometry>
    </collision>
  </link>
  <joint name="RR_calf_joint" type="revolute">
    <origin rpy="0 0 0" xyz="-0.448519 0.006079 -0.7266809999999999" />
    <parent link="RR_thigh" />
    <child link="RR_calf" />
    <axis xyz="0 1 0" />
    <dynamics damping="0.01" friction="0.2" />
    <limit effort="33.5" velocity="21" />
  </joint>
  <link name="RR_calf">
    <visual>
      <origin rpy="0 0 0" xyz="0 0 0" />
      <geometry>
        <sphere radius="0.1" /></geometry>
      <material name="orange" />
    </visual>
    <collision>
      <origin rpy="0 1.57079632679 0" xyz="0 0 -0.1" />
      <geometry>
        <box size="0.2 0.016 0.016" />
      </geometry>
    </collision>
  </link>
  <joint name="RR_foot_fixed" type="fixed">
    <origin rpy="0 0 0" xyz="-0.075565 0.033491 -0.44655" />
    <parent link="RR_calf" />
    <child link="RR_foot" />
  </joint>
  <link name="RR_foot">
    <visual>
      <origin rpy="0 0 0" xyz="0 0 0" />
      <geometry>
        <sphere radius="0.1" /></geometry>
      <material name="orange" />
    </visual>
    <collision>
      <origin rpy="0 0 0" xyz="0 0 0" />
      <geometry>
        <sphere radius="0.02" />
      </geometry>
    </collision>
  </link>


  
  <link name="Lower Spine"><visual><geometry><sphere radius="0.1" /></geometry></visual></link>

  <joint name="Spinal Midpoint Lower" type="revolute">
    <origin rpy="0 0 0" xyz="-0.562901 0.01244 0.0" />
    <parent link="trunk" />
    <child link="Lower Spine" />
    <axis xyz="0 1 0" />
    <dynamics damping="0.01" friction="0.2" />
    <limit effort="33.5" velocity="21" />
  </joint>

  <link name="Tail"><visual><geometry><sphere radius="0.1" /></geometry></visual></link>

  <joint name="Start of Tail" type="revolute">
    <origin rpy="0 0 0" xyz="-0.906485 0.020033 -0.732124" />
    <parent link="Lower Spine" />
    <child link="Tail" />
    <axis xyz="0 1 0" />
    <dynamics damping="0.01" friction="0.2" />
    <limit effort="33.5" velocity="21" />
  </joint>


  <link name="Upper Spine"><visual><geometry><sphere radius="0.1" /></geometry></visual></link>
  <link name="Ears"><visual><geometry><sphere radius="0.1" /></geometry></visual></link>
  <link name="Nose"><visual><geometry><sphere radius="0.1" /></geometry></visual></link>
  <link name="Jawline"><visual><geometry><sphere radius="0.1" /></geometry></visual></link>

  <joint name="Spinal Midpoint Upper" type="revolute">
    <origin rpy="0 0 0" xyz="0.494218 -0.010922000000000001 0.0" />
    <parent link="trunk" />
    <child link="Upper Spine" />
    <axis xyz="0 1 0" />
    <dynamics damping="0.01" friction="0.2" />
    <limit effort="33.5" velocity="21" />
  </joint>

  <joint name="Craniovertebral Junction" type="revolute">
    <origin rpy="0 0 0" xyz="1.1361700000000001 -0.025109 0.7563930000000001" />
    <parent link="Upper Spine" />
    <child link="Ears" />
    <axis xyz="0 1 0" />
    <dynamics damping="0.01" friction="0.2" />
    <limit effort="33.5" velocity="21" />
  </joint>

  <joint name="Top of Nose" type="revolute">
    <origin rpy="0 0 0" xyz="0.5705129999999999 -0.012608 -0.521657" />
    <parent link="Ears" />
    <child link="Nose" />
    <axis xyz="0 1 0" />
    <dynamics damping="0.01" friction="0.2" />
    <limit effort="33.5" velocity="21" />
  </joint>

  <joint name="Jaw" type="revolute">
    <origin rpy="0 0 0" xyz="-0.579458 0.012806 0.011843999999999999" />
    <parent link="Nose" />
    <child link="Jawline" />
    <axis xyz="0 1 0" />
    <dynamics damping="0.01" friction="0.2" />
    <limit effort="33.5" velocity="21" />
  </joint>

  <transmission name="RR_hip_tran">
    <type>transmission_interface/SimpleTransmission</type>
    <joint name="RR_hip_joint">
      <hardwareInterface>hardware_interface/EffortJointInterface</hardwareInterface>
    </joint>
    <actuator name="RR_hip_motor">
      <hardwareInterface>hardware_interface/EffortJointInterface</hardwareInterface>
      <mechanicalReduction>1</mechanicalReduction>
    </actuator>
  </transmission>
  <transmission name="RR_thigh_tran">
    <type>transmission_interface/SimpleTransmission</type>
    <joint name="RR_thigh_joint">
      <hardwareInterface>hardware_interface/EffortJointInterface</hardwareInterface>
    </joint>
    <actuator name="RR_thigh_motor">
      <hardwareInterface>hardware_interface/EffortJointInterface</hardwareInterface>
      <mechanicalReduction>1</mechanicalReduction>
    </actuator>
  </transmission>
  <transmission name="RR_calf_tran">
    <type>transmission_interface/SimpleTransmission</type>
    <joint name="RR_calf_joint">
      <hardwareInterface>hardware_interface/EffortJointInterface</hardwareInterface>
    </joint>
    <actuator name="RR_calf_motor">
      <hardwareInterface>hardware_interface/EffortJointInterface</hardwareInterface>
      <mechanicalReduction>1</mechanicalReduction>
    </actuator>
  </transmission>
    <link name="RL_pre_hip"><visual><geometry><sphere radius="0.1" /></geometry></visual></link>
    <joint name="RL_pre_hip_joint" type="revolute">
    <origin rpy="0 0 0" xyz="-0.5649419999999999 0.21976500000000002 -0.791156" />
    <parent link="trunk" />
    <child link="RL_pre_hip" />
    <axis xyz="0 1 0" />
    <dynamics damping="0.01" friction="0.2" />
    <limit effort="33.5" velocity="21" />
  </joint>
  <joint name="RL_hip_joint" type="revolute">
    <origin rpy="0 0 0" xyz="0.0 0.0 0.0" />
    <parent link="RL_pre_hip" />
    <child link="RL_hip" />
    <axis xyz="1 0 0" />
    <dynamics damping="0.01" friction="0.2" />
    <limit effort="33.5" velocity="21" />
  </joint>
  <link name="RL_hip">
    <visual>
      <origin rpy="0 3.14159265359 0" xyz="0 0 0" />
      <geometry>
        <sphere radius="0.1" /></geometry>
      <material name="orange" />
    </visual>
    <collision>
      <origin rpy="1.57079632679 0 0" xyz="0 0 0" />
      <geometry>
        <cylinder length="0.04" radius="0.046" />
      </geometry>
    </collision>
  </link>
  <joint name="RL_thigh_joint" type="revolute">
    <origin rpy="0 0 0" xyz="0.0 0.0 0.0" />
    <parent link="RL_hip" />
    <child link="RL_thigh" />
    <axis xyz="0 1 0" />
    <dynamics damping="0.01" friction="0.2" />
    <limit effort="33.5" velocity="21" />
  </joint>
  <link name="RL_thigh">
    <visual>
      <origin rpy="0 0 0" xyz="0 0 0" />
      <geometry>
        <sphere radius="0.1" /></geometry>
      <material name="orange" />
    </visual>
    <collision>
      <origin rpy="0 1.57079632679 0" xyz="0 0 -0.1" />
      <geometry>
        <box size="0.2 0.0245 0.034" />
      </geometry>
    </collision>
  </link>
  <joint name="RL_calf_joint" type="revolute">
    <origin rpy="0 0 0" xyz="-0.346984 0.012964 -0.7092059999999999" />
    <parent link="RL_thigh" />
    <child link="RL_calf" />
    <axis xyz="0 1 0" />
    <dynamics damping="0.01" friction="0.2" />
    <limit effort="33.5" velocity="21" />
  </joint>
  <link name="RL_calf">
    <visual>
      <origin rpy="0 0 0" xyz="0 0 0" />
      <geometry>
        <sphere radius="0.1" /></geometry>
      <material name="orange" />
    </visual>
    <collision>
      <origin rpy="0 1.57079632679 0" xyz="0 0 -0.1" />
      <geometry>
        <box size="0.2 0.016 0.016" />
      </geometry>
    </collision>
  </link>
  <joint name="RL_foot_fixed" type="fixed">
    <origin rpy="0 0 0" xyz="0.030973999999999998 -0.012686999999999999 -0.454922" />
    <parent link="RL_calf" />
    <child link="RL_foot" />
  </joint>
  <link name="RL_foot">
    <visual>
      <origin rpy="0 0 0" xyz="0 0 0" />
      <geometry>
        <sphere radius="0.1" /></geometry>
      <material name="orange" />
    </visual>
    <collision>
      <origin rpy="0 0 0" xyz="0 0 0" />
      <geometry>
        <sphere radius="0.02" />
      </geometry>
    </collision>
  </link>
  <transmission name="RL_hip_tran">
    <type>transmission_interface/SimpleTransmission</type>
    <joint name="RL_hip_joint">
      <hardwareInterface>hardware_interface/EffortJointInterface</hardwareInterface>
    </joint>
    <actuator name="RL_hip_motor">
      <hardwareInterface>hardware_interface/EffortJointInterface</hardwareInterface>
      <mechanicalReduction>1</mechanicalReduction>
    </actuator>
  </transmission>
  <transmission name="RL_thigh_tran">
    <type>transmission_interface/SimpleTransmission</type>
    <joint name="RL_thigh_joint">
      <hardwareInterface>hardware_interface/EffortJointInterface</hardwareInterface>
    </joint>
    <actuator name="RL_thigh_motor">
      <hardwareInterface>hardware_interface/EffortJointInterface</hardwareInterface>
      <mechanicalReduction>1</mechanicalReduction>
    </actuator>
  </transmission>
  <transmission name="RL_calf_tran">
    <type>transmission_interface/SimpleTransmission</type>
    <joint name="RL_calf_joint">
      <hardwareInterface>hardware_interface/EffortJointInterface</hardwareInterface>
    </joint>
    <actuator name="RL_calf_motor">
      <hardwareInterface>hardware_interface/EffortJointInterface</hardwareInterface>
      <mechanicalReduction>1</mechanicalReduction>
    </actuator>
  </transmission>
  
</robot>