<?xml version="1.0" encoding="utf-8"?>
<robot name="a1">
  
  
  
 
  <link name="base">
    <visual>
      <origin rpy="0 0 0" xyz="0 0 0" />
      <geometry>
        <box size="0.001 0.001 0.001" />
      </geometry>
    </visual>
  </link>
  <joint name="floating_base" type="fixed">
    <origin rpy="0 0 0" xyz="0.0000 0.0000 0.0000" />
    <parent link="base" />
    <child link="trunk" />
  </joint>
  <link name="trunk">
    <visual>
      <origin rpy="0 0 0" xyz="0 0 0" />
      <geometry>
        <mesh filename="package://a1_description/meshes/trunk.dae" scale="1 1 1" />
      </geometry>
      <material name="orange" />
    </visual>
    <collision>
      <origin rpy="0 0 0" xyz="0 0 0" />
      <geometry>
        <box size="0.267 0.194 0.114" />
      </geometry>
    </collision>
  </link>

  <joint name="FR_hip_joint" type="revolute">
    <origin rpy="0 0 0" xyz="90.2915 -24.6175 -95.3342" />
    <parent link="trunk" />
    <child link="FR_hip" />
    <axis xyz="1 0 0" />
    <dynamics damping="0.01" friction="0.2" />
    <limit effort="33.5" velocity="21" />
  </joint>
  <link name="FR_hip">
    <visual>
      <origin rpy="3.14159265359 0 0" xyz="0 0 0" />
      <geometry>
        <mesh filename="package://a1_description/meshes/hip.dae" scale="1 1 1" />
      </geometry>
      <material name="orange" />
    </visual>
    <collision>
      <origin rpy="1.57079632679 0 0" xyz="0 0 0" />
      <geometry>
        <cylinder length="0.04" radius="0.046" />
      </geometry>
    </collision>
  </link>
  <joint name="FR_thigh_joint" type="revolute">
    <origin rpy="0 0 0" xyz="0.0000 0.0000 0.0000" />
    <parent link="FR_hip" />
    <child link="FR_thigh" />
    <axis xyz="0 1 0" />
    <dynamics damping="0.01" friction="0.2" />
    <limit effort="33.5" velocity="21" />
  </joint>
  <link name="FR_thigh">
    <visual>
      <origin rpy="0 0 0" xyz="0 0 0" />
      <geometry>
        <mesh filename="package://a1_description/meshes/thigh_mirror.dae" scale="1 1 1" />
      </geometry>
      <material name="orange" />
    </visual>
    <collision>
      <origin rpy="0 1.57079632679 0" xyz="0 0 -0.1" />
      <geometry>
        <box size="0.2 0.0245 0.034" />
      </geometry>
    </collision>
  </link>
  <joint name="FR_calf_joint" type="revolute">
    <origin rpy="0 0 0" xyz="-5.4576 0.6502 -53.3053" />
    <parent link="FR_thigh" />
    <child link="FR_calf" />
    <axis xyz="0 1 0" />
    <dynamics damping="0.01" friction="0.2" />
    <limit effort="33.5" velocity="21" />
  </joint>
  <link name="FR_calf">
    <visual>
      <origin rpy="0 0 0" xyz="0 0 0" />
      <geometry>
        <mesh filename="package://a1_description/meshes/calf.dae" scale="1 1 1" />
      </geometry>
      <material name="orange" />
    </visual>
    <collision>
      <origin rpy="0 1.57079632679 0" xyz="0 0 -0.1" />
      <geometry>
        <box size="0.2 0.016 0.016" />
      </geometry>
    </collision>
  </link>
  <joint name="FR_foot_fixed" type="fixed">
    <origin rpy="0 0 0" xyz="-8.8321 -1.0051 -45.4922" />
    <parent link="FR_calf" />
    <child link="FR_foot" />
  </joint>
  <link name="FR_foot">
    <visual>
      <origin rpy="0 0 0" xyz="0 0 0" />
      <geometry>
        <sphere radius="0.01" />
      </geometry>
      <material name="orange" />
    </visual>
    <collision>
      <origin rpy="0 0 0" xyz="0 0 0" />
      <geometry>
        <sphere radius="0.02" />
      </geometry>
    </collision>
  </link>
  <transmission name="FR_hip_tran">
    <type>transmission_interface/SimpleTransmission</type>
    <joint name="FR_hip_joint">
      <hardwareInterface>hardware_interface/EffortJointInterface</hardwareInterface>
    </joint>
    <actuator name="FR_hip_motor">
      <hardwareInterface>hardware_interface/EffortJointInterface</hardwareInterface>
      <mechanicalReduction>1</mechanicalReduction>
    </actuator>
  </transmission>
  <transmission name="FR_thigh_tran">
    <type>transmission_interface/SimpleTransmission</type>
    <joint name="FR_thigh_joint">
      <hardwareInterface>hardware_interface/EffortJointInterface</hardwareInterface>
    </joint>
    <actuator name="FR_thigh_motor">
      <hardwareInterface>hardware_interface/EffortJointInterface</hardwareInterface>
      <mechanicalReduction>1</mechanicalReduction>
    </actuator>
  </transmission>
  <transmission name="FR_calf_tran">
    <type>transmission_interface/SimpleTransmission</type>
    <joint name="FR_calf_joint">
      <hardwareInterface>hardware_interface/EffortJointInterface</hardwareInterface>
    </joint>
    <actuator name="FR_calf_motor">
      <hardwareInterface>hardware_interface/EffortJointInterface</hardwareInterface>
      <mechanicalReduction>1</mechanicalReduction>
    </actuator>
  </transmission>
  <joint name="FL_hip_joint" type="revolute">
    <origin rpy="0 0 0" xyz="72.8557 19.1179 -96.7309" />
    <parent link="trunk" />
    <child link="FL_hip" />
    <axis xyz="1 0 0" />
    <dynamics damping="0.01" friction="0.2" />
    <limit effort="33.5" velocity="21" />
  </joint>
  <link name="FL_hip">
    <visual>
      <origin rpy="0 0 0" xyz="0 0 0" />
      <geometry>
        <mesh filename="package://a1_description/meshes/hip.dae" scale="1 1 1" />
      </geometry>
      <material name="orange" />
    </visual>
    <collision>
      <origin rpy="1.57079632679 0 0" xyz="0 0 0" />
      <geometry>
        <cylinder length="0.04" radius="0.046" />
      </geometry>
    </collision>
  </link>
  <joint name="FL_thigh_joint" type="revolute">
    <origin rpy="0 0 0" xyz="0.0000 0.0000 0.0000" />
    <parent link="FL_hip" />
    <child link="FL_thigh" />
    <axis xyz="0 1 0" />
    <dynamics damping="0.01" friction="0.2" />
    <limit effort="33.5" velocity="21" />
  </joint>
  <link name="FL_thigh">
    <visual>
      <origin rpy="0 0 0" xyz="0 0 0" />
      <geometry>
        <mesh filename="package://a1_description/meshes/thigh.dae" scale="1 1 1" />
      </geometry>
      <material name="orange" />
    </visual>
    <collision>
      <origin rpy="0 1.57079632679 0" xyz="0 0 -0.1" />
      <geometry>
        <box size="0.2 0.0245 0.034" />
      </geometry>
    </collision>
  </link>
  <joint name="FL_calf_joint" type="revolute">
    <origin rpy="0 0 0" xyz="-5.4575 0.6502 -53.3053" />
    <parent link="FL_thigh" />
    <child link="FL_calf" />
    <axis xyz="0 1 0" />
    <dynamics damping="0.01" friction="0.2" />
    <limit effort="33.5" velocity="21" />
  </joint>
  <link name="FL_calf">
    <visual>
      <origin rpy="0 0 0" xyz="0 0 0" />
      <geometry>
        <mesh filename="package://a1_description/meshes/calf.dae" scale="1 1 1" />
      </geometry>
      <material name="orange" />
    </visual>
    <collision>
      <origin rpy="0 1.57079632679 0" xyz="0 0 -0.1" />
      <geometry>
        <box size="0.2 0.016 0.016" />
      </geometry>
    </collision>
  </link>
  <joint name="FL_foot_fixed" type="fixed">
    <origin rpy="0 0 0" xyz="-8.8321 -1.0051 -45.4922" />
    <parent link="FL_calf" />
    <child link="FL_foot" />
  </joint>
  <link name="FL_foot">
    <visual>
      <origin rpy="0 0 0" xyz="0 0 0" />
      <geometry>
        <sphere radius="0.01" />
      </geometry>
      <material name="orange" />
    </visual>
    <collision>
      <origin rpy="0 0 0" xyz="0 0 0" />
      <geometry>
        <sphere radius="0.02" />
      </geometry>
    </collision>
  </link>
  <transmission name="FL_hip_tran">
    <type>transmission_interface/SimpleTransmission</type>
    <joint name="FL_hip_joint">
      <hardwareInterface>hardware_interface/EffortJointInterface</hardwareInterface>
    </joint>
    <actuator name="FL_hip_motor">
      <hardwareInterface>hardware_interface/EffortJointInterface</hardwareInterface>
      <mechanicalReduction>1</mechanicalReduction>
    </actuator>
  </transmission>
  <transmission name="FL_thigh_tran">
    <type>transmission_interface/SimpleTransmission</type>
    <joint name="FL_thigh_joint">
      <hardwareInterface>hardware_interface/EffortJointInterface</hardwareInterface>
    </joint>
    <actuator name="FL_thigh_motor">
      <hardwareInterface>hardware_interface/EffortJointInterface</hardwareInterface>
      <mechanicalReduction>1</mechanicalReduction>
    </actuator>
  </transmission>
  <transmission name="FL_calf_tran">
    <type>transmission_interface/SimpleTransmission</type>
    <joint name="FL_calf_joint">
      <hardwareInterface>hardware_interface/EffortJointInterface</hardwareInterface>
    </joint>
    <actuator name="FL_calf_motor">
      <hardwareInterface>hardware_interface/EffortJointInterface</hardwareInterface>
      <mechanicalReduction>1</mechanicalReduction>
    </actuator>
  </transmission>

  <joint name="RR_hip_joint" type="revolute">
    <origin rpy="0 0 0" xyz="-82.6344 -18.0470 -81.8491" />
    <parent link="trunk" />
    <child link="RR_hip" />
    <axis xyz="1 0 0" />
    <dynamics damping="0.01" friction="0.2" />
    <limit effort="33.5" velocity="21" />
  </joint>
  <link name="RR_hip">
    <visual>
      <origin rpy="3.14159265359 3.14159265359 0" xyz="0 0 0" />
      <geometry>
        <mesh filename="package://a1_description/meshes/hip.dae" scale="1 1 1" />
      </geometry>
      <material name="orange" />
    </visual>
    <collision>
      <origin rpy="1.57079632679 0 0" xyz="0 0 0" />
      <geometry>
        <cylinder length="0.04" radius="0.046" />
      </geometry>
    </collision>
  </link>
  <joint name="RR_thigh_joint" type="revolute">
    <origin rpy="0 0 0" xyz="0.0000 0.0000 0.0000" />
    <parent link="RR_hip" />
    <child link="RR_thigh" />
    <axis xyz="0 1 0" />
    <dynamics damping="0.01" friction="0.2" />
    <limit effort="33.5" velocity="21" />
  </joint>
  <link name="RR_thigh">
    <visual>
      <origin rpy="0 0 0" xyz="0 0 0" />
      <geometry>
        <mesh filename="package://a1_description/meshes/thigh_mirror.dae" scale="1 1 1" />
      </geometry>
      <material name="orange" />
    </visual>
    <collision>
      <origin rpy="0 1.57079632679 0" xyz="0 0 -0.1" />
      <geometry>
        <box size="0.2 0.0245 0.034" />
      </geometry>
    </collision>
  </link>
  <joint name="RR_calf_joint" type="revolute">
    <origin rpy="0 0 0" xyz="-44.8519 0.6079 -72.6681" />
    <parent link="RR_thigh" />
    <child link="RR_calf" />
    <axis xyz="0 1 0" />
    <dynamics damping="0.01" friction="0.2" />
    <limit effort="33.5" velocity="21" />
  </joint>
  <link name="RR_calf">
    <visual>
      <origin rpy="0 0 0" xyz="0 0 0" />
      <geometry>
        <mesh filename="package://a1_description/meshes/calf.dae" scale="1 1 1" />
      </geometry>
      <material name="orange" />
    </visual>
    <collision>
      <origin rpy="0 1.57079632679 0" xyz="0 0 -0.1" />
      <geometry>
        <box size="0.2 0.016 0.016" />
      </geometry>
    </collision>
  </link>
  <joint name="RR_foot_fixed" type="fixed">
    <origin rpy="0 0 0" xyz="-7.5565 3.3491 -44.6550" />
    <parent link="RR_calf" />
    <child link="RR_foot" />
  </joint>
  <link name="RR_foot">
    <visual>
      <origin rpy="0 0 0" xyz="0 0 0" />
      <geometry>
        <sphere radius="0.01" />
      </geometry>
      <material name="orange" />
    </visual>
    <collision>
      <origin rpy="0 0 0" xyz="0 0 0" />
      <geometry>
        <sphere radius="0.02" />
      </geometry>
    </collision>
  </link>


  
  <link name="Lower Spine" />

  <joint name="Spinal Midpoint Lower" type="revolute">
    <origin rpy="0 0 0" xyz="-56.2901 1.2440 0.0000" />
    <parent link="trunk" />
    <child link="Lower Spine" />
    <axis xyz="0 1 0" />
    <dynamics damping="0.01" friction="0.2" />
    <limit effort="33.5" velocity="21" />
  </joint>

  <link name="Tail" />

  <joint name="Start of Tail" type="revolute">
    <origin rpy="0 0 0" xyz="-90.6485 2.0033 -73.2124" />
    <parent link="Lower Spine" />
    <child link="Tail" />
    <axis xyz="0 1 0" />
    <dynamics damping="0.01" friction="0.2" />
    <limit effort="33.5" velocity="21" />
  </joint>


  <link name="Upper Spine" />
  <link name="Ears" />
  <link name="Nose" />
  <link name="Jawline" />

  <joint name="Spinal Midpoint Upper" type="revolute">
    <origin rpy="0 0 0" xyz="49.4218 -1.0922 0.0000" />
    <parent link="trunk" />
    <child link="Upper Spine" />
    <axis xyz="0 1 0" />
    <dynamics damping="0.01" friction="0.2" />
    <limit effort="33.5" velocity="21" />
  </joint>

  <joint name="Craniovertebral Junction" type="revolute">
    <origin rpy="0 0 0" xyz="113.6170 -2.5109 75.6393" />
    <parent link="Upper Spine" />
    <child link="Ears" />
    <axis xyz="0 1 0" />
    <dynamics damping="0.01" friction="0.2" />
    <limit effort="33.5" velocity="21" />
  </joint>

  <joint name="Top of Nose" type="revolute">
    <origin rpy="0 0 0" xyz="57.0513 -1.2608 -52.1657" />
    <parent link="Ears" />
    <child link="Nose" />
    <axis xyz="0 1 0" />
    <dynamics damping="0.01" friction="0.2" />
    <limit effort="33.5" velocity="21" />
  </joint>

  <joint name="Jaw" type="revolute">
    <origin rpy="0 0 0" xyz="-57.9458 1.2806 1.1844" />
    <parent link="Nose" />
    <child link="Jawline" />
    <axis xyz="0 1 0" />
    <dynamics damping="0.01" friction="0.2" />
    <limit effort="33.5" velocity="21" />
  </joint>

  <transmission name="RR_hip_tran">
    <type>transmission_interface/SimpleTransmission</type>
    <joint name="RR_hip_joint">
      <hardwareInterface>hardware_interface/EffortJointInterface</hardwareInterface>
    </joint>
    <actuator name="RR_hip_motor">
      <hardwareInterface>hardware_interface/EffortJointInterface</hardwareInterface>
      <mechanicalReduction>1</mechanicalReduction>
    </actuator>
  </transmission>
  <transmission name="RR_thigh_tran">
    <type>transmission_interface/SimpleTransmission</type>
    <joint name="RR_thigh_joint">
      <hardwareInterface>hardware_interface/EffortJointInterface</hardwareInterface>
    </joint>
    <actuator name="RR_thigh_motor">
      <hardwareInterface>hardware_interface/EffortJointInterface</hardwareInterface>
      <mechanicalReduction>1</mechanicalReduction>
    </actuator>
  </transmission>
  <transmission name="RR_calf_tran">
    <type>transmission_interface/SimpleTransmission</type>
    <joint name="RR_calf_joint">
      <hardwareInterface>hardware_interface/EffortJointInterface</hardwareInterface>
    </joint>
    <actuator name="RR_calf_motor">
      <hardwareInterface>hardware_interface/EffortJointInterface</hardwareInterface>
      <mechanicalReduction>1</mechanicalReduction>
    </actuator>
  </transmission>
  <joint name="RL_hip_joint" type="revolute">
    <origin rpy="0 0 0" xyz="-56.4942 21.9765 -79.1156" />
    <parent link="trunk" />
    <child link="RL_hip" />
    <axis xyz="1 0 0" />
    <dynamics damping="0.01" friction="0.2" />
    <limit effort="33.5" velocity="21" />
  </joint>
  <link name="RL_hip">
    <visual>
      <origin rpy="0 3.14159265359 0" xyz="0 0 0" />
      <geometry>
        <mesh filename="package://a1_description/meshes/hip.dae" scale="1 1 1" />
      </geometry>
      <material name="orange" />
    </visual>
    <collision>
      <origin rpy="1.57079632679 0 0" xyz="0 0 0" />
      <geometry>
        <cylinder length="0.04" radius="0.046" />
      </geometry>
    </collision>
  </link>
  <joint name="RL_thigh_joint" type="revolute">
    <origin rpy="0 0 0" xyz="0.0000 0.0000 0.0000" />
    <parent link="RL_hip" />
    <child link="RL_thigh" />
    <axis xyz="0 1 0" />
    <dynamics damping="0.01" friction="0.2" />
    <limit effort="33.5" velocity="21" />
  </joint>
  <link name="RL_thigh">
    <visual>
      <origin rpy="0 0 0" xyz="0 0 0" />
      <geometry>
        <mesh filename="package://a1_description/meshes/thigh.dae" scale="1 1 1" />
      </geometry>
      <material name="orange" />
    </visual>
    <collision>
      <origin rpy="0 1.57079632679 0" xyz="0 0 -0.1" />
      <geometry>
        <box size="0.2 0.0245 0.034" />
      </geometry>
    </collision>
  </link>
  <joint name="RL_calf_joint" type="revolute">
    <origin rpy="0 0 0" xyz="-34.6984 1.2964 -70.9206" />
    <parent link="RL_thigh" />
    <child link="RL_calf" />
    <axis xyz="0 1 0" />
    <dynamics damping="0.01" friction="0.2" />
    <limit effort="33.5" velocity="21" />
  </joint>
  <link name="RL_calf">
    <visual>
      <origin rpy="0 0 0" xyz="0 0 0" />
      <geometry>
        <mesh filename="package://a1_description/meshes/calf.dae" scale="1 1 1" />
      </geometry>
      <material name="orange" />
    </visual>
    <collision>
      <origin rpy="0 1.57079632679 0" xyz="0 0 -0.1" />
      <geometry>
        <box size="0.2 0.016 0.016" />
      </geometry>
    </collision>
  </link>
  <joint name="RL_foot_fixed" type="fixed">
    <origin rpy="0 0 0" xyz="3.0974 -1.2687 -45.4922" />
    <parent link="RL_calf" />
    <child link="RL_foot" />
  </joint>
  <link name="RL_foot">
    <visual>
      <origin rpy="0 0 0" xyz="0 0 0" />
      <geometry>
        <sphere radius="0.01" />
      </geometry>
      <material name="orange" />
    </visual>
    <collision>
      <origin rpy="0 0 0" xyz="0 0 0" />
      <geometry>
        <sphere radius="0.02" />
      </geometry>
    </collision>
  </link>
  <transmission name="RL_hip_tran">
    <type>transmission_interface/SimpleTransmission</type>
    <joint name="RL_hip_joint">
      <hardwareInterface>hardware_interface/EffortJointInterface</hardwareInterface>
    </joint>
    <actuator name="RL_hip_motor">
      <hardwareInterface>hardware_interface/EffortJointInterface</hardwareInterface>
      <mechanicalReduction>1</mechanicalReduction>
    </actuator>
  </transmission>
  <transmission name="RL_thigh_tran">
    <type>transmission_interface/SimpleTransmission</type>
    <joint name="RL_thigh_joint">
      <hardwareInterface>hardware_interface/EffortJointInterface</hardwareInterface>
    </joint>
    <actuator name="RL_thigh_motor">
      <hardwareInterface>hardware_interface/EffortJointInterface</hardwareInterface>
      <mechanicalReduction>1</mechanicalReduction>
    </actuator>
  </transmission>
  <transmission name="RL_calf_tran">
    <type>transmission_interface/SimpleTransmission</type>
    <joint name="RL_calf_joint">
      <hardwareInterface>hardware_interface/EffortJointInterface</hardwareInterface>
    </joint>
    <actuator name="RL_calf_motor">
      <hardwareInterface>hardware_interface/EffortJointInterface</hardwareInterface>
      <mechanicalReduction>1</mechanicalReduction>
    </actuator>
  </transmission>
  
</robot>